Workbook

Sheet Отчет
A1: Итоговый отчёт | T1: =IFERROR(V1/U1,0) -> 0.500449 | U1: =SUM(U3:U340) -> 4.7421114e+08 | V1: =SUM(V3:V340) -> 2.3731849e+08
A2: Код товара | B2: Наименование русс. | C2: Артикул | D2: Brembo | E2: Группа заказа | F2: Категория NEW | G2: Группа NEW | H2: Подгруппа NEW | I2: Закупочная цена валюта | J2: Закупочная цена | K2: МО Валюта | L2: МО | M2: Разновидность | N2: Продажи(2025) | O2: Остаток | P2: Категория ABC | Q2: СБС | R2: СБС план | S2: Кат. А | T2: ВР 1 | U2: Сумма продажи | V2: Сумма прибыли | W2: Brambo | X2: Откл | AB2: Код | AC2: Отклонение к конк.1, % | AD2: Ratio конк.1, % | AE2: Разница конк.1, руб | AF2: Уровень конк.1 | AG2: Отклонение к конк.2, % | AH2: Ratio конк.2, % | AI2: Разница конк.2, руб | AJ2: Уровень конк.2 | AK2: Среднее отклонение, % | AL2: Макс. разница, руб | AM2: Итоговый уровень (число) | AN2: Итоговый уровень | AO2: Вес продаж К1 | AP2: Вклад продаж К1 | AQ2: Вес остатка К1, руб | AR2: Вклад остатка К1 | AS2: Вес продаж К2 | AT2: Вклад продаж К2 | AU2: Вес остатка К2, руб | AV2: Вклад остатка К2
A3: 130909 | B3: Диск тормозной пер. ADVICS | C3: A6F164B | D3: 09A41711 | E3: Продукция ADVICS | F3: ДЕТАЛИ ТОРМОЗНОЙ СИСТЕМЫ | G3: Тормозные диски | H3: Стандартные тормозные диски | I3: JPY | J3: 1572.8194 | K3: U2JPY | L3: 4859.8036 | M3: (F) TOYOTA CAMRY V40 (06-11), CAMRY V50 (11-17), RAV4 A30 (06-12) | N3: 8665 | O3: 141 | P3: A | Q3: 2210 | R3: 2154.7626 | S3: 4130.833 | T3: 0.48754836 | U3: 35793668 | V3: 17451144 | W3: 3460.75 | X3: =1-(S3/W3) -> -0.19362364 | AB3: =A3 -> 130909 | AC3: =IFERROR(IF(OR(NOT(ISNUMBER(S3)),NOT(ISNUMBER(W3))),"",IF(OR(S3<=0,W3<=0),"",(1-S3/W3)*100)),"") -> -19.362364 | AD3: =IF(AC3="","",(MAX(S3,W3)/MIN(S3,W3)-1)*100) -> 19.362364 | AE3: =IF(AC3="","",ABS(W3-S3)) -> 670.08302 | AF3: =IF(AC3="","",IF(AND(AE3<MAX(Расч!$B$11,S3*Расч!$B$12),IF(AD3<Расч!$B$7,0,IF(AD3<Расч!$B$8,1,IF(AD3<Расч!$B$9,2,IF(AD3<Расч!$B$10,3,4))))>1),1,IF(AD3<Расч!$B$7,0,IF(AD3<Расч!$B$8,1,IF(AD3<Расч!$B$9,2,IF(AD3<Расч!$B$10,3,4)))))) -> 0 | AK3: =IF(AC3="","",AC3) -> -19.362364 | AL3: =IF(AE3="","",AE3) -> 670.08302 | AM3: =IF(AF3="","",AF3) -> 0 | AN3: =IF(AM3="","нет данных",CHOOSE(AM3+1,"Норма","Лёгкое отклонение","Заметный разброс","Выброс","Экстремальный выброс")) -> Норма | AO3: =IF(OR(AC3="",NOT(ISNUMBER(N3))),0,MAX(N3,0)) -> 8665 | AP3: =IF(AC3="",0,AC3*AO3) -> -167774.89 | AQ3: =IF(OR(AC3="",NOT(ISNUMBER(O3))),0,MAX(O3,0)*S3) -> 582447.46 | AR3: =IF(AC3="",0,AC3*AQ3) -> -11277560
A4: 130887 | B4: Диск тормозной зад. ADVICS | C4: A6R135B | D4: 09A96710 | E4: Продукция ADVICS | F4: ДЕТАЛИ ТОРМОЗНОЙ СИСТЕМЫ | G4: Тормозные диски | H4: Стандартные тормозные диски | I4: JPY | J4: 1802.5571 | K4: U2JPY | L4: 5723.2443 | M4: (R) TOYOTA LAND CRUISER J200 (07-), LEXUS LX570 (07-) | N4: 5756 | O4: 397 | P4: A | Q4: 2488 | R4: 2469.5032 | S4: 4864.7577 | T4: 0.50784456 | U4: 28001545 | V4: 14220432 | W4: 0
A5: 1774891 | B5: Диск тормозной пер. ADVICS | C5: A6F828B | E5: Продукция ADVICS | F5: ДЕТАЛИ ТОРМОЗНОЙ СИСТЕМЫ | G5: Тормозные диски | H5: Стандартные тормозные диски | I5: JPY | J5: 1831.2743 | K5: U2JPY | L5: 6012.8557 | M5: (Fr) TOYOTA CAMRY #V7; RAV4 AXA5# | N5: 5287 | O5: 12 | P5: A | Q5: 2606 | R5: 2508.8457 | S5: 5110.9273 | T5: 0.51102521 | U5: 27021473 | V5: 13808654 | W5: 0
A6: 130919 | B6: Диск тормозной пер. ADVICS | C6: A6F159B | D6: 09B63410 | E6: Продукция ADVICS | F6: ДЕТАЛИ ТОРМОЗНОЙ СИСТЕМЫ | G6: Тормозные диски | H6: Стандартные тормозные диски | I6: JPY | J6: 1907.4853 | K6: U2JPY | L6: 6367.2893 | M6: (F) TOYOTA LAND CRUISER PRADO J150 (09-), 4RUNNER N280 (09-), LEXUS GX460 J150 (09-) | N6: 4909 | O6: 379 | P6: A | Q6: 2689 | R6: 2613.2549 | S6: 5412.1959 | T6: 0.53790297 | U6: 26568470 | V6: 14291259 | W6: 0
A7: 156230 | B7: Диск тормозной зад. ADVICS | C7: A6R161B | D7: 09A33421 | E7: Продукция ADVICS | F7: ДЕТАЛИ ТОРМОЗНОЙ СИСТЕМЫ | G7: Тормозные диски | H7: Стандартные тормозные диски | I7: JPY | J7: 1731.3163 | K7: U2JPY | L7: 5174.7548 | M7: (R) TOYOTA LAND CRUISER PRADO J150 (09-) | N7: 4531 | O7: 312 | P7: A | Q7: 2393 | R7: 2371.9033 | S7: 4398.5416 | T7: 0.47162981 | U7: 19929792 | V7: 9399484 | W7: 4467.9 | X7: =1-(S7/W7) -> 0.015523712 | AB7: =A7 -> 156230 | AC7: =IFERROR(IF(OR(NOT(ISNUMBER(S7)),NOT(ISNUMBER(W7))),"",IF(OR(S7<=0,W7<=0),"",(1-S7/W7)*100)),"") -> 1.5523712 | AD7: =IF(AC7="","",(MAX(S7,W7)/MIN(S7,W7)-1)*100) -> 1.5768498 | AE7: =IF(AC7="","",ABS(W7-S7)) -> 69.358394 | AF7: =IF(AC7="","",IF(AND(AE7<MAX(Расч!$B$11,S7*Расч!$B$12),IF(AD7<Расч!$B$7,0,IF(AD7<Расч!$B$8,1,IF(AD7<Расч!$B$9,2,IF(AD7<Расч!$B$10,3,4))))>1),1,IF(AD7<Расч!$B$7,0,IF(AD7<Расч!$B$8,1,IF(AD7<Расч!$B$9,2,IF(AD7<Расч!$B$10,3,4)))))) -> 0 | AK7: =IF(AC7="","",AC7) -> 1.5523712 | AL7: =IF(AE7="","",AE7) -> 69.358394 | AM7: =IF(AF7="","",AF7) -> 0 | AN7: =IF(AM7="","нет данных",CHOOSE(AM7+1,"Норма","Лёгкое отклонение","Заметный разброс","Выброс","Экстремальный выброс")) -> Норма | AO7: =IF(OR(AC7="",NOT(ISNUMBER(N7))),0,MAX(N7,0)) -> 4531 | AP7: =IF(AC7="",0,AC7*AO7) -> 7033.794 | AQ7: =IF(OR(AC7="",NOT(ISNUMBER(O7))),0,MAX(O7,0)*S7) -> 1372345 | AR7: =IF(AC7="",0,AC7*AQ7) -> 2130388.9
A8: 130918 | B8: Диск тормозной пер. ADVICS | C8: A6F153B | D8: 09A96611 | E8: Продукция ADVICS | F8: ДЕТАЛИ ТОРМОЗНОЙ СИСТЕМЫ | G8: Тормозные диски | H8: Стандартные тормозные диски | I8: JPY | J8: 2136.6707 | K8: U2JPY | L8: 6535.8854 | M8: (F) TOYOTA LAND CRUISER J200 (07-15), LEXUS LX570 J200 (07-15) | N8: 3536 | O8: 373 | P8: A | Q8: 2982 | R8: 2927.2389 | S8: 5555.5026 | T8: 0.49141555 | U8: 19644257 | V8: 9653493.4 | W8: 9289.23 | X8: =1-(S8/W8) -> 0.40194154 | AB8: =A8 -> 130918 | AC8: =IFERROR(IF(OR(NOT(ISNUMBER(S8)),NOT(ISNUMBER(W8))),"",IF(OR(S8<=0,W8<=0),"",(1-S8/W8)*100)),"") -> 40.194154 | AD8: =IF(AC8="","",(MAX(S8,W8)/MIN(S8,W8)-1)*100) -> 67.207734 | AE8: =IF(AC8="","",ABS(W8-S8)) -> 3733.7274 | AF8: =IF(AC8="","",IF(AND(AE8<MAX(Расч!$B$11,S8*Расч!$B$12),IF(AD8<Расч!$B$7,0,IF(AD8<Расч!$B$8,1,IF(AD8<Расч!$B$9,2,IF(AD8<Расч!$B$10,3,4))))>1),1,IF(AD8<Расч!$B$7,0,IF(AD8<Расч!$B$8,1,IF(AD8<Расч!$B$9,2,IF(AD8<Расч!$B$10,3,4)))))) -> 3 | AK8: =IF(AC8="","",AC8) -> 40.194154 | AL8: =IF(AE8="","",AE8) -> 3733.7274 | AM8: =IF(AF8="","",AF8) -> 3 | AN8: =IF(AM8="","нет данных",CHOOSE(AM8+1,"Норма","Лёгкое отклонение","Заметный разброс","Выброс","Экстремальный выброс")) -> Выброс | AO8: =IF(OR(AC8="",NOT(ISNUMBER(N8))),0,MAX(N8,0)) -> 3536 | AP8: =IF(AC8="",0,AC8*AO8) -> 142126.53 | AQ8: =IF(OR(AC8="",NOT(ISNUMBER(O8))),0,MAX(O8,0)*S8) -> 2072202.5 | AR8: =IF(AC8="",0,AC8*AQ8) -> 83290425
A9: 170242 | B9: Диск тормозной пер. ADVICS | C9: A6F535B | E9: Продукция ADVICS | F9: ДЕТАЛИ ТОРМОЗНОЙ СИСТЕМЫ | G9: Тормозные диски | H9: Стандартные тормозные диски | I9: JPY | J9: 2246.017 | K9: U2JPY | L9: 6981.7996 | M9: (F) LEXUS LX 450d (15-), TOYOTA LAND CRUISER J200 (15-), TUNDRA UCK60 (07-) | N9: 3507 | O9: 176 | P9: A | Q9: 3083 | R9: 3077.0433 | S9: 5934.5296 | T9: 0.49291702 | U9: 20812395 | V9: 10258784 | W9: 0
A10: 156219 | B10: Диск тормозной зад. ADVICS | C10: A6R208B | D10: 08D41811 | E10: Продукция ADVICS | F10: ДЕТАЛИ ТОРМОЗНОЙ СИСТЕМЫ | G10: Тормозные диски | H10: Стандартные тормозные диски | I10: JPY | J10: 1202.8092 | K10: U2JPY | L10: 4069.1466 | M10: (R) CAMRY #V70 / RAV4 #A50 / LEXUS NX AGZ10 (14-) | N10: 3373 | O10: 157 | P10: A | Q10: 1694 | R10: 1647.8486 | S10: 3458.7746 | T10: 0.53156196 | U10: 11666447 | V10: 6201439.3 | W10: 0
A11: 130913 | B11: Диск тормозной пер. ADVICS | C11: A6F147B | D11: 09C49911 | E11: Продукция ADVICS | F11: ДЕТАЛИ ТОРМОЗНОЙ СИСТЕМЫ | G11: Тормозные диски | H11: Стандартные тормозные диски | I11: JPY | J11: 1995.846 | K11: U2JPY | L11: 5751.0155 | M11: (F) LEXUS RX GGL10 / GGL15 (08-15), TOYOTA HIGHLANDER GSU45 (08-13), HIGHLANDER GSU55 (13-) | N11: 3371 | O11: 111 | P11: A | Q11: 2780 | R11: 2734.309 | S11: 4888.3632 | T11: 0.4462205 | U11: 16478672 | V11: 7353121.4 | W11: 5703.93 | X11: =1-(S11/W11) -> 0.14298331 | AB11: =A11 -> 130913 | AC11: =IFERROR(IF(OR(NOT(ISNUMBER(S11)),NOT(ISNUMBER(W11))),"",IF(OR(S11<=0,W11<=0),"",(1-S11/W11)*100)),"") -> 14.298331 | AD11: =IF(AC11="","",(MAX(S11,W11)/MIN(S11,W11)-1)*100) -> 16.683843 | AE11: =IF(AC11="","",ABS(W11-S11)) -> 815.56681 | AF11: =IF(AC11="","",IF(AND(AE11<MAX(Расч!$B$11,S11*Расч!$B$12),IF(AD11<Расч!$B$7,0,IF(AD11<Расч!$B$8,1,IF(AD11<Расч!$B$9,2,IF(AD11<Расч!$B$10,3,4))))>1),1,IF(AD11<Расч!$B$7,0,IF(AD11<Расч!$B$8,1,IF(AD11<Расч!$B$9,2,IF(AD11<Расч!$B$10,3,4)))))) -> 0 | AK11: =IF(AC11="","",AC11) -> 14.298331 | AL11: =IF(AE11="","",AE11) -> 815.56681 | AM11: =IF(AF11="","",AF11) -> 0 | AN11: =IF(AM11="","нет данных",CHOOSE(AM11+1,"Норма","Лёгкое отклонение","Заметный разброс","Выброс","Экстремальный выброс")) -> Норма | AO11: =IF(OR(AC11="",NOT(ISNUMBER(N11))),0,MAX(N11,0)) -> 3371 | AP11: =IF(AC11="",0,AC11*AO11) -> 48199.675 | AQ11: =IF(OR(AC11="",NOT(ISNUMBER(O11))),0,MAX(O11,0)*S11) -> 542608.31 | AR11: =IF(AC11="",0,AC11*AQ11) -> 7758393.5
A12: 170245 | B12: Диск тормозной пер. ADVICS | C12: A6F540B | E12: Продукция ADVICS | F12: ДЕТАЛИ ТОРМОЗНОЙ СИСТЕМЫ | G12: Тормозные диски | H12: Стандартные тормозные диски | I12: JPY | J12: 2036.7128 | K12: U2JPY | L12: 6142.2605 | M12: (F) LEXUS RX AL20 (15-) | N12: 2625 | O12: 182 | P12: A | Q12: 2809 | R12: 2790.2965 | S12: 5220.9214 | T12: 0.48434117 | U12: 13704919 | V12: 6637856.3 | W12: 0
A13: 156208 | B13: Диск тормозной пер. ADVICS | C13: E6F200B | D13: 09C65411 | E13: Продукция ADVICS | F13: ДЕТАЛИ ТОРМОЗНОЙ СИСТЕМЫ | G13: Тормозные диски | H13: Стандартные тормозные диски | I13: JPY | J13: 1666.1503 | K13: U2JPY | L13: 5302.3105 | M13: (F) MAZDA CX-5 KE (12-17) / MAZDA 6 GJ (12-) | N13: 2420 | O13: 248 | P13: A | Q13: 2383 | R13: 2282.6259 | S13: 4506.9639 | T13: 0.4935602 | U13: 10906853 | V13: 5383188.4 | W13: 4886.82 | X13: =1-(S13/W13) -> 0.077730723 | AB13: =A13 -> 156208 | AC13: =IFERROR(IF(OR(NOT(ISNUMBER(S13)),NOT(ISNUMBER(W13))),"",IF(OR(S13<=0,W13<=0),"",(1-S13/W13)*100)),"") -> 7.7730723 | AD13: =IF(AC13="","",(MAX(S13,W13)/MIN(S13,W13)-1)*100) -> 8.4282026 | AE13: =IF(AC13="","",ABS(W13-S13)) -> 379.85605 | AF13: =IF(AC13="","",IF(AND(AE13<MAX(Расч!$B$11,S13*Расч!$B$12),IF(AD13<Расч!$B$7,0,IF(AD13<Расч!$B$8,1,IF(AD13<Расч!$B$9,2,IF(AD13<Расч!$B$10,3,4))))>1),1,IF(AD13<Расч!$B$7,0,IF(AD13<Расч!$B$8,1,IF(AD13<Расч!$B$9,2,IF(AD13<Расч!$B$10,3,4)))))) -> 0 | AK13: =IF(AC13="","",AC13) -> 7.7730723 | AL13: =IF(AE13="","",AE13) -> 379.85605 | AM13: =IF(AF13="","",AF13) -> 0 | AN13: =IF(AM13="","нет данных",CHOOSE(AM13+1,"Норма","Лёгкое отклонение","Заметный разброс","Выброс","Экстремальный выброс")) -> Норма | AO13: =IF(OR(AC13="",NOT(ISNUMBER(N13))),0,MAX(N13,0)) -> 2420 | AP13: =IF(AC13="",0,AC13*AO13) -> 18810.835 | AQ13: =IF(OR(AC13="",NOT(ISNUMBER(O13))),0,MAX(O13,0)*S13) -> 1117727.1 | AR13: =IF(AC13="",0,AC13*AQ13) -> 8688173.2
A14: 130895 | B14: Диск тормозной зад. ADVICS | C14: A6R180B | D14: 09A33410 | E14: Продукция ADVICS | F14: ДЕТАЛИ ТОРМОЗНОЙ СИСТЕМЫ | G14: Тормозные диски | H14: Стандартные тормозные диски | I14: JPY | J14: 1678.2999 | K14: U2JPY | L14: 5054.082 | M14: (R) TOYOTA LAND CRUISER PRADO J120 (02-09), FJ CRUISER GSJ15 (06-14), LEXUS GX470 J120 (02-09) | N14: 1668 | O14: 186 | P14: A | Q14: 2265 | R14: 2299.2709 | S14: 4295.9697 | T14: 0.49339156 | U14: 7165677.5 | V14: 3535484.8 | W14: 0
A15: 130891 | B15: Диск тормозной зад. ADVICS | C15: A6R083B | E15: Продукция ADVICS | F15: ДЕТАЛИ ТОРМОЗНОЙ СИСТЕМЫ | G15: Тормозные диски | H15: Стандартные тормозные диски | I15: JPY | J15: 1379.5305 | K15: U2JPY | L15: 4388.8919 | M15: (R) TOYOTA CAMRY V40 (06-12), CAMRY V50 (11-17) | N15: 1563 | O15: 161 | P15: A | Q15: 1940 | R15: 1889.9568 | S15: 3730.5581 | T15: 0.50310551 | U15: 5830862.3 | V15: 2933539 | W15: 0
A16: 170263 | B16: Диск тормозной зад. ADVICS | C16: A6R545B | E16: Продукция ADVICS | F16: ДЕТАЛИ ТОРМОЗНОЙ СИСТЕМЫ | G16: Тормозные диски | H16: Стандартные тормозные диски | I16: JPY | J16: 1774.9444 | K16: U2JPY | L16: 5647.7211 | M16: (R) LEXUS RX AL20 (15-) | N16: 1521 | O16: 114 | P16: B | Q16: 2407 | R16: 2431.6738 | S16: 4800.5629 | T16: 0.50904639 | U16: 7301656.2 | V16: 3716881.7 | W16: 0
A17: 130892 | B17: Диск тормозной зад. ADVICS | C17: A6R078B | D17: 08A42910 | E17: Продукция ADVICS | F17: ДЕТАЛИ ТОРМОЗНОЙ СИСТЕМЫ | G17: Тормозные диски | H17: Стандартные тормозные диски | I17: JPY | J17: 1485.011 | K17: U2JPY | L17: 4351.5326 | M17: (R) TOYOTA RAV4 A30 (06-12), RAV4 A40 (12- ) | N17: 1501 | O17: 10 | P17: B | Q17: 2049 | R17: 2034.4651 | S17: 3698.8027 | T17: 0.47728653 | U17: 5551902.9 | V17: 2649848.5 | W17: 2806.54 | X17: =1-(S17/W17) -> -0.31792268 | AB17: =A17 -> 130892 | AC17: =IFERROR(IF(OR(NOT(ISNUMBER(S17)),NOT(ISNUMBER(W17))),"",IF(OR(S17<=0,W17<=0),"",(1-S17/W17)*100)),"") -> -31.792268 | AD17: =IF(AC17="","",(MAX(S17,W17)/MIN(S17,W17)-1)*100) -> 31.792268 | AE17: =IF(AC17="","",ABS(W17-S17)) -> 892.26273 | AF17: =IF(AC17="","",IF(AND(AE17<MAX(Расч!$B$11,S17*Расч!$B$12),IF(AD17<Расч!$B$7,0,IF(AD17<Расч!$B$8,1,IF(AD17<Расч!$B$9,2,IF(AD17<Расч!$B$10,3,4))))>1),1,IF(AD17<Расч!$B$7,0,IF(AD17<Расч!$B$8,1,IF(AD17<Расч!$B$9,2,IF(AD17<Расч!$B$10,3,4)))))) -> 1 | AK17: =IF(AC17="","",AC17) -> -31.792268 | AL17: =IF(AE17="","",AE17) -> 892.26273 | AM17: =IF(AF17="","",AF17) -> 1 | AN17: =IF(AM17="","нет данных",CHOOSE(AM17+1,"Норма","Лёгкое отклонение","Заметный разброс","Выброс","Экстремальный выброс")) -> Лёгкое отклонение | AO17: =IF(OR(AC17="",NOT(ISNUMBER(N17))),0,MAX(N17,0)) -> 1501 | AP17: =IF(AC17="",0,AC17*AO17) -> -47720.195 | AQ17: =IF(OR(AC17="",NOT(ISNUMBER(O17))),0,MAX(O17,0)*S17) -> 36988.027 | AR17: =IF(AC17="",0,AC17*AQ17) -> -1175933.3
A18: 130916 | B18: Диск тормозной пер. ADVICS | C18: A6F182B | D18: 09A20411 | E18: Продукция ADVICS | F18: ДЕТАЛИ ТОРМОЗНОЙ СИСТЕМЫ | G18: Тормозные диски | H18: Стандартные тормозные диски | I18: JPY | J18: 1872.1411 | K18: U2JPY | L18: 5939.9178 | M18: (F) TOYOTA LAND CRUISER PRADO J120 (02-09), LEXUS GX470 J120 (02-09) | N18: 1421 | O18: 188 | P18: B | Q18: 2637 | R18: 2564.8333 | S18: 5048.9301 | T18: 0.4989131 | U18: 7174529.7 | V18: 3579466.8 | W18: 4603.31 | X18: =1-(S18/W18) -> -0.096804283 | AB18: =A18 -> 130916 | AC18: =IFERROR(IF(OR(NOT(ISNUMBER(S18)),NOT(ISNUMBER(W18))),"",IF(OR(S18<=0,W18<=0),"",(1-S18/W18)*100)),"") -> -9.6804283 | AD18: =IF(AC18="","",(MAX(S18,W18)/MIN(S18,W18)-1)*100) -> 9.6804283 | AE18: =IF(AC18="","",ABS(W18-S18)) -> 445.62012 | AF18: =IF(AC18="","",IF(AND(AE18<MAX(Расч!$B$11,S18*Расч!$B$12),IF(AD18<Расч!$B$7,0,IF(AD18<Расч!$B$8,1,IF(AD18<Расч!$B$9,2,IF(AD18<Расч!$B$10,3,4))))>1),1,IF(AD18<Расч!$B$7,0,IF(AD18<Расч!$B$8,1,IF(AD18<Расч!$B$9,2,IF(AD18<Расч!$B$10,3,4)))))) -> 0 | AK18: =IF(AC18="","",AC18) -> -9.6804283 | AL18: =IF(AE18="","",AE18) -> 445.62012 | AM18: =IF(AF18="","",AF18) -> 0 | AN18: =IF(AM18="","нет данных",CHOOSE(AM18+1,"Норма","Лёгкое отклонение","Заметный разброс","Выброс","Экстремальный выброс")) -> Норма | AO18: =IF(OR(AC18="",NOT(ISNUMBER(N18))),0,MAX(N18,0)) -> 1421 | AP18: =IF(AC18="",0,AC18*AO18) -> -13755.889 | AQ18: =IF(OR(AC18="",NOT(ISNUMBER(O18))),0,MAX(O18,0)*S18) -> 949198.86 | AR18: =IF(AC18="",0,AC18*AQ18) -> -9188651.6
A19: 163783 | B19: Диск тормозной пер. ADVICS | C19: D6F141B | D19: 09A63721 | E19: Продукция ADVICS | F19: ДЕТАЛИ ТОРМОЗНОЙ СИСТЕМЫ | G19: Тормозные диски | H19: Стандартные тормозные диски | I19: JPY | J19: 1504.8921 | K19: U2JPY | L19: 5300.3929 | M19: (F) MITSUBISHI ASX GA4W (10-) | N19: 1131 | O19: 94 | P19: B | Q19: 2138 | R19: 2061.7022 | S19: 4505.334 | T19: 0.54536168 | U19: 5095532.7 | V19: 2778908.3 | W19: 0
A20: 156213 | B20: Диск тормозной пер. ADVICS | C20: F6F125B | D20: 9907711 | E20: Продукция ADVICS | F20: ДЕТАЛИ ТОРМОЗНОЙ СИСТЕМЫ | G20: Тормозные диски | H20: Стандартные тормозные диски | I20: JPY | J20: 1570.0581 | K20: U2JPY | L20: 4911.3737 | M20: (F) SUBARU FORESTER SJ (12-) | N20: 1011 | O20: 87 | P20: B | Q20: 2255 | R20: 2150.9796 | S20: 4174.6677 | T20: 0.48035082 | U20: 4220589 | V20: 2027363.4 | W20: 0
A21: 170244 | B21: Диск тормозной пер. ADVICS | C21: A6F537B | E21: Продукция ADVICS | F21: ДЕТАЛИ ТОРМОЗНОЙ СИСТЕМЫ | G21: Тормозные диски | H21: Стандартные тормозные диски | I21: JPY | J21: 2232.7629 | K21: U2JPY | L21: 8051.6238 | M21: (F) LEXUS RX 450h GYL15L (12-15) | N21: 980 | O21: 30 | P21: B | Q21: 3075 | R21: 3058.8852 | S21: 6843.8802 | T21: 0.57135532 | U21: 6707002.6 | V21: 3832081.6 | W21: 0
A22: 156215 | B22: Диск тормозной пер. ADVICS | C22: A6F127B | D22: 09A86414 | E22: Продукция ADVICS | F22: ДЕТАЛИ ТОРМОЗНОЙ СИСТЕМЫ | G22: Тормозные диски | H22: Стандартные тормозные диски | I22: JPY | J22: 1530.8481 | K22: U2JPY | L22: 4923.667 | M22: (F) TOYOTA COROLLA E150 (06-12) | N22: 952 | O22: 38 | P22: B | Q22: 2193 | R22: 2097.2619 | S22: 4185.117 | T22: 0.51310133 | U22: 3984231.3 | V22: 2044314.4 | W22: 0
A23: 163776 | B23: Диск тормозной пер. ADVICS | C23: A6F227B | D23: 09B62711 | E23: Продукция ADVICS | F23: ДЕТАЛИ ТОРМОЗНОЙ СИСТЕМЫ | G23: Тормозные диски | H23: Стандартные тормозные диски | I23: JPY | J23: 1738.4956 | K23: U2JPY | L23: 5618.7514 | M23: (F) TOYOTA HILUX GUN126L (15-) | N23: 824 | O23: 28 | P23: B | Q23: 2433 | R23: 2381.739 | S23: 4775.9387 | T23: 0.51161714 | U23: 3935373.5 | V23: 2013404.5 | W23: 0
A24: 156209 | B24: Диск тормозной пер. ADVICS | C24: B6F207B | E24: Продукция ADVICS | F24: ДЕТАЛИ ТОРМОЗНОЙ СИСТЕМЫ | G24: Тормозные диски | H24: Стандартные тормозные диски | I24: JPY | J24: 1871.0366 | K24: U2JPY | L24: 6024.2415 | M24: (F) NISSAN MURANO Z52R (15-), PATHFINDER R52R (14-) | N24: 768 | O24: 41 | P24: B | Q24: 2711 | R24: 2563.3201 | S24: 5120.6053 | T24: 0.49338765 | U24: 3932624.9 | V24: 1940308.6 | W24: 0
A25: 163780 | B25: Диск тормозной пер. ADVICS | C25: A6F115B | D25: 09A10911 | E25: Продукция ADVICS | F25: ДЕТАЛИ ТОРМОЗНОЙ СИСТЕМЫ | G25: Тормозные диски | H25: Стандартные тормозные диски | I25: JPY | J25: 1878.2159 | K25: U2JPY | L25: 5930.2441 | M25: (F) LEXUS RX 350 GSU35L (03-08), TOYOTA HARRER XU30 (03-12) | N25: 736 | O25: 171 | P25: B | Q25: 2766 | R25: 2573.1557 | S25: 5040.7075 | T25: 0.472948 | U25: 3709960.7 | V25: 1754618.5 | W25: 0
A26: 130894 | B26: Диск тормозной зад. ADVICS | C26: A6R094B | E26: Продукция ADVICS | F26: ДЕТАЛИ ТОРМОЗНОЙ СИСТЕМЫ | G26: Тормозные диски | H26: Стандартные тормозные диски | I26: JPY | J26: 1758.3767 | K26: U2JPY | L26: 5644.0571 | M26: (R) LEXUS RX GGL10 / GGL15 (08-15), TOYOTA HIGHLANDER GSU45 (08-13), HIGHLANDER GSU55 (13-) | N26: 730 | O26: 29 | P26: B | Q26: 2465 | R26: 2408.9761 | S26: 4797.4485 | T26: 0.50873886 | U26: 3502137.4 | V26: 1781673.4 | W26: 0
A27: 130930 | B27: Диск тормозной пер. ADVICS | C27: C6F129B | D27: 09A86610 | E27: Продукция ADVICS | F27: ДЕТАЛИ ТОРМОЗНОЙ СИСТЕМЫ | G27: Тормозные диски | H27: Стандартные тормозные диски | I27: JPY | J27: 1731.3163 | K27: U2JPY | L27: 5618.7514 | M27: (F) HONDA CR-V RE (06-11), CR-V RM (11-16), CROSSTOUR TF (09-15) | N27: 701 | O27: 45 | P27: B | Q27: 2502 | R27: 2371.9033 | S27: 4775.9387 | T27: 0.49834611 | U27: 3347933 | V27: 1668429.4 | W27: 4749.2 | X27: =1-(S27/W27) -> -0.0056301432 | AB27: =A27 -> 130930 | AC27: =IFERROR(IF(OR(NOT(ISNUMBER(S27)),NOT(ISNUMBER(W27))),"",IF(OR(S27<=0,W27<=0),"",(1-S27/W27)*100)),"") -> -0.56301432 | AD27: =IF(AC27="","",(MAX(S27,W27)/MIN(S27,W27)-1)*100) -> 0.56301432 | AE27: =IF(AC27="","",ABS(W27-S27)) -> 26.738676 | AF27: =IF(AC27="","",IF(AND(AE27<MAX(Расч!$B$11,S27*Расч!$B$12),IF(AD27<Расч!$B$7,0,IF(AD27<Расч!$B$8,1,IF(AD27<Расч!$B$9,2,IF(AD27<Расч!$B$10,3,4))))>1),1,IF(AD27<Расч!$B$7,0,IF(AD27<Расч!$B$8,1,IF(AD27<Расч!$B$9,2,IF(AD27<Расч!$B$10,3,4)))))) -> 0 | AK27: =IF(AC27="","",AC27) -> -0.56301432 | AL27: =IF(AE27="","",AE27) -> 26.738676 | AM27: =IF(AF27="","",AF27) -> 0 | AN27: =IF(AM27="","нет данных",CHOOSE(AM27+1,"Норма","Лёгкое отклонение","Заметный разброс","Выброс","Экстремальный выброс")) -> Норма | AO27: =IF(OR(AC27="",NOT(ISNUMBER(N27))),0,MAX(N27,0)) -> 701 | AP27: =IF(AC27="",0,AC27*AO27) -> -394.67304 | AQ27: =IF(OR(AC27="",NOT(ISNUMBER(O27))),0,MAX(O27,0)*S27) -> 214917.24 | AR27: =IF(AC27="",0,AC27*AQ27) -> -121001.48
A28: 130876 | B28: Диск тормозной пер. ADVICS | C28: B6F162B | D28: 09A71611 | E28: Продукция ADVICS | F28: ДЕТАЛИ ТОРМОЗНОЙ СИСТЕМЫ | G28: Тормозные диски | H28: Стандартные тормозные диски | I28: JPY | J28: 1372.3512 | K28: U2JPY | L28: 4866.5152 | M28: (F) NISSAN QASHQAI / DUALIS J10 (07-13), X-TRAIL T31 (07-13), JUKE F15 (10-) | N28: 700 | O28: 29 | P28: B | Q28: 1957 | R28: 1880.1211 | S28: 4136.5379 | T28: 0.54937712 | U28: 2895576.5 | V28: 1590763.5 | W28: 3988.3 | X28: =1-(S28/W28) -> -0.037168198 | AB28: =A28 -> 130876 | AC28: =IFERROR(IF(OR(NOT(ISNUMBER(S28)),NOT(ISNUMBER(W28))),"",IF(OR(S28<=0,W28<=0),"",(1-S28/W28)*100)),"") -> -3.7168198 | AD28: =IF(AC28="","",(MAX(S28,W28)/MIN(S28,W28)-1)*100) -> 3.7168198 | AE28: =IF(AC28="","",ABS(W28-S28)) -> 148.23792 | AF28: =IF(AC28="","",IF(AND(AE28<MAX(Расч!$B$11,S28*Расч!$B$12),IF(AD28<Расч!$B$7,0,IF(AD28<Расч!$B$8,1,IF(AD28<Расч!$B$9,2,IF(AD28<Расч!$B$10,3,4))))>1),1,IF(AD28<Расч!$B$7,0,IF(AD28<Расч!$B$8,1,IF(AD28<Расч!$B$9,2,IF(AD28<Расч!$B$10,3,4)))))) -> 0 | AK28: =IF(AC28="","",AC28) -> -3.7168198 | AL28: =IF(AE28="","",AE28) -> 148.23792 | AM28: =IF(AF28="","",AF28) -> 0 | AN28: =IF(AM28="","нет данных",CHOOSE(AM28+1,"Норма","Лёгкое отклонение","Заметный разброс","Выброс","Экстремальный выброс")) -> Норма | AO28: =IF(OR(AC28="",NOT(ISNUMBER(N28))),0,MAX(N28,0)) -> 700 | AP28: =IF(AC28="",0,AC28*AO28) -> -2601.7739 | AQ28: =IF(OR(AC28="",NOT(ISNUMBER(O28))),0,MAX(O28,0)*S28) -> 119959.6 | AR28: =IF(AC28="",0,AC28*AQ28) -> -445868.22
A29: 130890 | B29: Диск тормозной зад. ADVICS | C29: A6R113B | D29: 09C93011 | E29: Продукция ADVICS | F29: ДЕТАЛИ ТОРМОЗНОЙ СИСТЕМЫ | G29: Тормозные диски | H29: Стандартные тормозные диски | I29: JPY | J29: 1537.4751 | K29: U2JPY | L29: 5676.6908 | M29: (R) LEXUS GS S190 (05-12), TOYOTA MARK X X120 (03-09), MARK X X130 (09-) | N29: 681 | O29: 55 | P29: B | Q29: 2169 | R29: 2106.3409 | S29: 4825.1872 | T29: 0.57009197 | U29: 3285952.5 | V29: 1873295.1 | W29: 4460.13 | X29: =1-(S29/W29) -> -0.081848995 | AB29: =A29 -> 130890 | AC29: =IFERROR(IF(OR(NOT(ISNUMBER(S29)),NOT(ISNUMBER(W29))),"",IF(OR(S29<=0,W29<=0),"",(1-S29/W29)*100)),"") -> -8.1848995 | AD29: =IF(AC29="","",(MAX(S29,W29)/MIN(S29,W29)-1)*100) -> 8.1848995 | AE29: =IF(AC29="","",ABS(W29-S29)) -> 365.05716 | AF29: =IF(AC29="","",IF(AND(AE29<MAX(Расч!$B$11,S29*Расч!$B$12),IF(AD29<Расч!$B$7,0,IF(AD29<Расч!$B$8,1,IF(AD29<Расч!$B$9,2,IF(AD29<Расч!$B$10,3,4))))>1),1,IF(AD29<Расч!$B$7,0,IF(AD29<Расч!$B$8,1,IF(AD29<Расч!$B$9,2,IF(AD29<Расч!$B$10,3,4)))))) -> 0 | AK29: =IF(AC29="","",AC29) -> -8.1848995 | AL29: =IF(AE29="","",AE29) -> 365.05716 | AM29: =IF(AF29="","",AF29) -> 0 | AN29: =IF(AM29="","нет данных",CHOOSE(AM29+1,"Норма","Лёгкое отклонение","Заметный разброс","Выброс","Экстремальный выброс")) -> Норма | AO29: =IF(OR(AC29="",NOT(ISNUMBER(N29))),0,MAX(N29,0)) -> 681 | AP29: =IF(AC29="",0,AC29*AO29) -> -5573.9166 | AQ29: =IF(OR(AC29="",NOT(ISNUMBER(O29))),0,MAX(O29,0)*S29) -> 265385.29 | AR29: =IF(AC29="",0,AC29*AQ29) -> -2172152
A30: 156211 | B30: Диск тормозной пер. ADVICS | C30: B6F194B | D30: 09C54511 | E30: Продукция ADVICS | F30: ДЕТАЛИ ТОРМОЗНОЙ СИСТЕМЫ | G30: Тормозные диски | H30: Стандартные тормозные диски | I30: JPY | J30: 1841.2148 | K30: U2JPY | L30: 5910.2804 | M30: (F) NISSAN QASHQAI J11E (13-), X-TRAIL T32R (14-) | N30: 665 | O30: 63 | P30: B | Q30: 2602 | R30: 2522.4643 | S30: 5023.7383 | T30: 0.51264902 | U30: 3340786 | V30: 1712650.6 | W30: 4790.9 | X30: =1-(S30/W30) -> -0.048600117 | AB30: =A30 -> 156211 | AC30: =IFERROR(IF(OR(NOT(ISNUMBER(S30)),NOT(ISNUMBER(W30))),"",IF(OR(S30<=0,W30<=0),"",(1-S30/W30)*100)),"") -> -4.8600117 | AD30: =IF(AC30="","",(MAX(S30,W30)/MIN(S30,W30)-1)*100) -> 4.8600117 | AE30: =IF(AC30="","",ABS(W30-S30)) -> 232.8383 | AF30: =IF(AC30="","",IF(AND(AE30<MAX(Расч!$B$11,S30*Расч!$B$12),IF(AD30<Расч!$B$7,0,IF(AD30<Расч!$B$8,1,IF(AD30<Расч!$B$9,2,IF(AD30<Расч!$B$10,3,4))))>1),1,IF(AD30<Расч!$B$7,0,IF(AD30<Расч!$B$8,1,IF(AD30<Расч!$B$9,2,IF(AD30<Расч!$B$10,3,4)))))) -> 0 | AK30: =IF(AC30="","",AC30) -> -4.8600117 | AL30: =IF(AE30="","",AE30) -> 232.8383 | AM30: =IF(AF30="","",AF30) -> 0 | AN30: =IF(AM30="","нет данных",CHOOSE(AM30+1,"Норма","Лёгкое отклонение","Заметный разброс","Выброс","Экстремальный выброс")) -> Норма | AO30: =IF(OR(AC30="",NOT(ISNUMBER(N30))),0,MAX(N30,0)) -> 665 | AP30: =IF(AC30="",0,AC30*AO30) -> -3231.9078 | AQ30: =IF(OR(AC30="",NOT(ISNUMBER(O30))),0,MAX(O30,0)*S30) -> 316495.51 | AR30: =IF(AC30="",0,AC30*AQ30) -> -1538171.9
A31: 156214 | B31: Диск тормозной пер. ADVICS | C31: A6F143B | D31: 09C71011 | E31: Продукция ADVICS | F31: ДЕТАЛИ ТОРМОЗНОЙ СИСТЕМЫ | G31: Тормозные диски | H31: Стандартные тормозные диски | I31: JPY | J31: 1768.3173 | K31: U2JPY | L31: 5675.8518 | M31: (F) TOYOTA ALPHARD GGH20 (08-15) | N31: 655 | O31: 18 | P31: B | Q31: 2418 | R31: 2422.5947 | S31: 4824.474 | T31: 0.52501155 | U31: 3160030.5 | V31: 1659052.5 | W31: 4939.4 | X31: =1-(S31/W31) -> 0.023267189 | AB31: =A31 -> 156214 | AC31: =IFERROR(IF(OR(NOT(ISNUMBER(S31)),NOT(ISNUMBER(W31))),"",IF(OR(S31<=0,W31<=0),"",(1-S31/W31)*100)),"") -> 2.3267189 | AD31: =IF(AC31="","",(MAX(S31,W31)/MIN(S31,W31)-1)*100) -> 2.3821447 | AE31: =IF(AC31="","",ABS(W31-S31)) -> 114.92595 | AF31: =IF(AC31="","",IF(AND(AE31<MAX(Расч!$B$11,S31*Расч!$B$12),IF(AD31<Расч!$B$7,0,IF(AD31<Расч!$B$8,1,IF(AD31<Расч!$B$9,2,IF(AD31<Расч!$B$10,3,4))))>1),1,IF(AD31<Расч!$B$7,0,IF(AD31<Расч!$B$8,1,IF(AD31<Расч!$B$9,2,IF(AD31<Расч!$B$10,3,4)))))) -> 0 | AK31: =IF(AC31="","",AC31) -> 2.3267189 | AL31: =IF(AE31="","",AE31) -> 114.92595 | AM31: =IF(AF31="","",AF31) -> 0 | AN31: =IF(AM31="","нет данных",CHOOSE(AM31+1,"Норма","Лёгкое отклонение","Заметный разброс","Выброс","Экстремальный выброс")) -> Норма | AO31: =IF(OR(AC31="",NOT(ISNUMBER(N31))),0,MAX(N31,0)) -> 655 | AP31: =IF(AC31="",0,AC31*AO31) -> 1524.0009 | AQ31: =IF(OR(AC31="",NOT(ISNUMBER(O31))),0,MAX(O31,0)*S31) -> 86840.533 | AR31: =IF(AC31="",0,AC31*AQ31) -> 202053.51
A32: 130896 | B32: Диск тормозной зад. ADVICS | C32: A6R173B | D32: 9908610 | E32: Продукция ADVICS | F32: ДЕТАЛИ ТОРМОЗНОЙ СИСТЕМЫ | G32: Тормозные диски | H32: Стандартные тормозные диски | I32: JPY | J32: 1660.0755 | K32: U2JPY | L32: 5870.3186 | M32: (R) TOYOTA LAND CRUISER J100 (98-07), LEXUS LX470 J100 (98-07) | N32: 653 | O32: 104 | P32: B | Q32: 2376 | R32: 2274.3035 | S32: 4989.7708 | T32: 0.54196104 | U32: 3258320.3 | V32: 1765882.7 | W32: 0
A33: 163777 | B33: Диск тормозной пер. ADVICS | C33: A6F228B | E33: Продукция ADVICS | F33: ДЕТАЛИ ТОРМОЗНОЙ СИСТЕМЫ | G33: Тормозные диски | H33: Стандартные тормозные диски | I33: JPY | J33: 1835.14 | K33: U2JPY | L33: 5890.4365 | M33: (F) TOYOTA VENZA AGV15L / GGV15L (08-16) | N33: 643 | O33: 88 | P33: B | Q33: 2715 | R33: 2514.1419 | S33: 5006.871 | T33: 0.48008078 | U33: 3219418 | V33: 1545580.7 | W33: 0
A34: 170259 | B34: Диск тормозной пер. ADVICS правый | C34: A6F543B | E34: Продукция ADVICS | F34: ДЕТАЛИ ТОРМОЗНОЙ СИСТЕМЫ | G34: Тормозные диски | H34: Стандартные тормозные диски | I34: JPY | J34: 2246.017 | K34: U2JPY | L34: 7209.5507 | M34: (FR) LEXUS GS 350 GRS196L (05-11) | N34: 613 | O34: 16 | P34: B | Q34: 3094 | R34: 3077.0433 | S34: 6128.1181 | T34: 0.51349737 | U34: 3756536.4 | V34: 1928971.6 | W34: 0
A35: 170264 | B35: Диск тормозной зад. ADVICS | C35: A6R538B | E35: Продукция ADVICS | F35: ДЕТАЛИ ТОРМОЗНОЙ СИСТЕМЫ | G35: Тормозные диски | H35: Стандартные тормозные диски | I35: JPY | J35: 1664.4936 | K35: U2JPY | L35: 5344.0872 | M35: (R) LEXUS RX GGL15L / GYL15L (12-15) | N35: 609 | O35: 30 | P35: B | Q35: 2296 | R35: 2280.3562 | S35: 4542.4741 | T35: 0.51421077 | U35: 2766366.7 | V35: 1422495.6 | W35: 0
A36: 156228 | B36: Диск тормозной зад. ADVICS | C36: A6R081B | D36: 08A53420 | E36: Продукция ADVICS | F36: ДЕТАЛИ ТОРМОЗНОЙ СИСТЕМЫ | G36: Тормозные диски | H36: Стандартные тормозные диски | I36: JPY | J36: 1202.8092 | K36: U2JPY | L36: 3864.0302 | M36: (R) TOYOTA COROLLA E150 (06-12) | N36: 593 | O36: 19 | P36: B | Q36: 1719 | R36: 1647.8486 | S36: 3284.4256 | T36: 0.50013901 | U36: 1947664.4 | V36: 974102.95 | W36: 0
A37: 1714636 | B37: Диск тормозной зад. ADVICS | C37: A6R598B | E37: Продукция ADVICS | F37: ДЕТАЛИ ТОРМОЗНОЙ СИСТЕМЫ | G37: Тормозные диски | H37: Стандартные тормозные диски | I37: JPY | J37: 1531.4003 | K37: U2JPY | L37: 4916.9382 | M37: (R) HIGHLANDER XU40 2007-2013 | N37: 589 | O37: 50 | P37: B | Q37: 2205 | R37: 2098.0185 | S37: 4179.3975 | T37: 0.49468122 | U37: 2461665.1 | V37: 1217739.5 | W37: 0
A38: 130873 | B38: Диск тормозной пер. ADVICS | C38: F6F126B | D38: 09A87011 | E38: Продукция ADVICS | F38: ДЕТАЛИ ТОРМОЗНОЙ СИСТЕМЫ | G38: Тормозные диски | H38: Стандартные тормозные диски | I38: JPY | J38: 1767.7651 | K38: U2JPY | L38: 5673.8828 | M38: (F) SUBARU LEGACY BL / BP (03-09) | N38: 576 | O38: 8 | P38: B | Q38: 2473 | R38: 2421.8381 | S38: 4822.8004 | T38: 0.50407799 | U38: 2777933 | V38: 1400294.9 | W38: 0
A39: 174293 | B39: Диск тормозной пер. ADVICS левый | C39: A6F544B | E39: Продукция ADVICS | F39: ДЕТАЛИ ТОРМОЗНОЙ СИСТЕМЫ | G39: Тормозные диски | H39: Стандартные тормозные диски | I39: JPY | J39: 2246.017 | K39: U2JPY | L39: 7209.5507 | M39: (FL) LEXUS GS 350 GRS196L (05-11) | N39: 573 | O39: 33 | P39: B | Q39: 3097 | R39: 3077.0433 | S39: 6128.1181 | T39: 0.51524246 | U39: 3511411.7 | V39: 1809228.4 | W39: 0
A40: 1752051 | B40: Диск тормозной пер. ADVICS | C40: A6F256B | E40: Продукция ADVICS | F40: ДЕТАЛИ ТОРМОЗНОЙ СИСТЕМЫ | G40: Тормозные диски | H40: Стандартные тормозные диски | I40: JPY | J40: 1306.0807 | K40: U2JPY | L40: 4411.3383 | M40: (F) TOYOTA COROLLA 140, 160 (07-12), VITZ 90, 130 (05-14), RACTIS 100 (06-08) BELTA 90 (06-09), PASSO SETTE (09-12), PORTE (12-), SPADE (12-) | N40: 517 | O40: 208 | P40: B | Q40: 1861 | R40: 1789.3306 | S40: 3749.6375 | T40: 0.52540457 | U40: 1938562.6 | V40: 1018529.7 | W40: 0
...

Sheet PriceAnalysisSettings
A1: SRC_SHEET | B1: Отчет
A2: COL_OWN | B2: 19
A3: COL_C1 | B3: 23
A4: HAS_C2 | B4: FALSE
A5: COL_C2 | B5: 0
A6: HAS_CAT | B6: TRUE
A7: COL_CAT | B7: 16
A8: HAS_SALES | B8: TRUE
A9: COL_SALES | B9: 14
A10: FIRST_ROW | B10: 3
A11: HAS_STOCK | B11: TRUE
A12: COL_STOCK | B12: 15
A13: HAS_CODE | B13: TRUE
A14: COL_CODE | B14: 1

Sheet Расч
A1: МЕТОДИЧКА: как считается анализ цен конкурентов
A2: Лист-источник: Отчет Строк в расчёте: 338 Пересчитано: 05.09.2026 13:22
A3: ПАРАМЕТРЫ РАСЧЁТА - эти ячейки можно менять руками, все формулы пересчитаются
A4: Медиана Ratio по выборке, % | B4: 16.673
A5: MAD (медианное абсолютное отклонение), % | B5: 8.358
A6: MADn = MAD x 1.4826, % | B6: 12.392
A7: Порог T1: Норма / Лёгкое отклонение, % | B7: 29.065
A8: Порог T2: Лёгкое / Заметный разброс, % | B8: 41.457
A9: Порог T3: Заметный / Выброс, % | B9: 53.849
A10: Порог T4: Выброс / Экстремальный, % | B10: 78.632
A11: Минимальная значимая разница, руб | B11: 300
A12: Минимальная значимая разница, доля от нашей цены | B12: 0.05
A13: Полоса паритета (плюс-минус), % | B13: 3

Sheet Сводка по брендам
A1: Показатель | B1: Brambo, %
A2: Среднее отклонение (все позиции), % | B2: =IFERROR(AVERAGE(Отчет!$AC$3:$AC$340),"нет данных") -> 0.27333014
A3: Отклонение по категории A (все позиции), % | B3: =IFERROR(AVERAGEIFS(Отчет!$AC$3:$AC$340,Отчет!$P$3:$P$340,"A"),"нет данных") -> 8.8911129
A4: Отклонение по категории B (все позиции), % | B4: =IFERROR(AVERAGEIFS(Отчет!$AC$3:$AC$340,Отчет!$P$3:$P$340,"B"),"нет данных") -> -2.8392112
A5: Отклонение по категории C (все позиции), % | B5: =IFERROR(AVERAGEIFS(Отчет!$AC$3:$AC$340,Отчет!$P$3:$P$340,"C"),"нет данных") -> 0.52024354
A6: Среднее без выбросов (мягкая очистка), % | B6: =IFERROR(AVERAGEIFS(Отчет!$AC$3:$AC$340,Отчет!$AF$3:$AF$340,"<>4"),"нет данных") -> -3.1279257
A7: Отклонение по категории A (мягкая), % | B7: =IFERROR(AVERAGEIFS(Отчет!$AC$3:$AC$340,Отчет!$P$3:$P$340,"A",Отчет!$AF$3:$AF$340,"<>4"),"нет данных") -> 8.8911129
A8: Отклонение по категории B (мягкая), % | B8: =IFERROR(AVERAGEIFS(Отчет!$AC$3:$AC$340,Отчет!$P$3:$P$340,"B",Отчет!$AF$3:$AF$340,"<>4"),"нет данных") -> -2.8392112
A9: Отклонение по категории C (мягкая), % | B9: =IFERROR(AVERAGEIFS(Отчет!$AC$3:$AC$340,Отчет!$P$3:$P$340,"C",Отчет!$AF$3:$AF$340,"<>4"),"нет данных") -> -4.2990108
A10: Среднее без выбросов (грубая очистка), % | B10: =IFERROR(AVERAGEIFS(Отчет!$AC$3:$AC$340,Отчет!$AF$3:$AF$340,"<2"),"нет данных") -> -4.1294647
A11: Отклонение по категории A (грубая), % | B11: =IFERROR(AVERAGEIFS(Отчет!$AC$3:$AC$340,Отчет!$P$3:$P$340,"A",Отчет!$AF$3:$AF$340,"<2"),"нет данных") -> 1.0653527
A12: Отклонение по категории B (грубая), % | B12: =IFERROR(AVERAGEIFS(Отчет!$AC$3:$AC$340,Отчет!$P$3:$P$340,"B",Отчет!$AF$3:$AF$340,"<2"),"нет данных") -> -4.7423372
A13: Отклонение по категории C (грубая), % | B13: =IFERROR(AVERAGEIFS(Отчет!$AC$3:$AC$340,Отчет!$P$3:$P$340,"C",Отчет!$AF$3:$AF$340,"<2"),"нет данных") -> -4.3283946
A14: Сигма (стандартное отклонение), % | B14: =IFERROR(STDEV(Отчет!$AC$3:$AC$340),"нет данных") -> 27.011255
A15: Медиана отклонения, % | B15: =IFERROR(MEDIAN(Отчет!$AC$3:$AC$340),"нет данных") -> -2.1707535
A16: Средневзвешенное отклонение (по продажам), % | B16: =IF(SUM(Отчет!$AO$3:$AO$340)=0,"нет данных",SUM(Отчет!$AP$3:$AP$340)/SUM(Отчет!$AO$3:$AO$340)) -> -1.7731275
A17: Средневзвешенное отклонение (по остаткам), % | B17: =IF(SUM(Отчет!$AQ$3:$AQ$340)=0,"нет данных",SUM(Отчет!$AR$3:$AR$340)/SUM(Отчет!$AQ$3:$AQ$340)) -> 6.867178
A19: ПОЗИЦИОНИРОВАНИЕ | B19: 10
A21: Позиций в расчёте, шт | B21: =COUNT(Отчет!$AC$3:$AC$340) -> 89
A22: Доля позиций, где мы дешевле, % | B22: =IF(B21=0,"нет данных",COUNTIF(Отчет!$AC$3:$AC$340,">"&Расч!$B$13)/B21*100) -> 42.696629
A23: Доля позиций, где мы дороже, % | B23: =IF(B21=0,"нет данных",COUNTIF(Отчет!$AC$3:$AC$340,"<-"&Расч!$B$13)/B21*100) -> 49.438202
A24: Доля позиций в паритете, % | B24: =IF(B21=0,"нет данных",100-B22-B23) -> 7.8651685
A25: Доля позиций с серьёзным расхождением (Выброс и выше), % | B25: =IF(B21=0,"нет данных",COUNTIF(Отчет!$AF$3:$AF$340,">=3")/B21*100) -> 12.359551
A26: Деньги в остатках по таким позициям, руб | B26: =IF(SUM(Отчет!$AQ$3:$AQ$340)=0,"нет данных",SUMIFS(Отчет!$AQ$3:$AQ$340,Отчет!$AF$3:$AF$340,">=3")) -> 2104921.2
